<?xml version="1.0" encoding="utf-8"?>
<!-- =================================================================================== -->
<!-- |    This document was autogenerated by xacro from arms_xacro.urdf.xacro          | -->
<!-- |    EDITING THIS FILE BY HAND IS NOT RECOMMENDED                                 | -->
<!-- =================================================================================== -->
<robot name="robot_arm">
  <!--    link-->
  <!-- Used for fixing robot to Gazebo 'base_link' -->
  <link name="world"/>
  <link name="upper_arm">
    <visual>
      <origin rpy="0 1.57079632679 0" xyz="0.5 0 0"/>
      <geometry>
        <cylinder length="1" radius="0.2"/>
      </geometry>
      <material name="arm_grey_mat">
        <color rgba="0.75 0.75 0.75 1.0"/>
      </material>
    </visual>
    <collision>
      <origin rpy="0 1.57079632679 0" xyz="0.5 0 0"/>
      <geometry>
        <cylinder length="1" radius="0.2"/>
      </geometry>
    </collision>
    <inertial>
      <mass value="0.1"/>
      <inertia ixx="0.03" ixy="0.0" ixz="0.0" iyy="0.03" iyz="0.0" izz="0.03"/>
    </inertial>
    <!--        <gazebo>-->
    <!--            <minDepth>-->
    <!--        </gazebo>-->
  </link>
  <joint name="base_link_upper_arm" type="revolute">
    <origin rpy="0 0 0" xyz="0.0 0.0 0.0"/>
    <parent link="world"/>
    <child link="upper_arm"/>
    <limit effort="100" lower="-3.142" upper="3.142" velocity="100"/>
    <axis xyz="0 0 1"/>
    <gazebo>
      <dynamics damping="0.01"/>
      <dynamics friction="0.01"/>
    </gazebo>
    <!--        ??not sure if this is necessary, should be specified in a gazebo file??-->
    <safety_controller k_position="100.0" k_velocity="40.0" soft_lower_limit="-3.142" soft_upper_limit="3.142"/>
  </joint>
  <link name="lower_arm">
    <visual>
      <origin rpy="0 1.57079632679 0" xyz="0.5 0 0"/>
      <geometry>
        <cylinder length="1" radius="0.1"/>
      </geometry>
      <material name="arm_grey_mat">
        <color rgba="0.75 0.75 0.75 1.0"/>
      </material>
    </visual>
    <collision>
      <origin rpy="0 1.57079632679 0" xyz="0.5 0 0"/>
      <geometry>
        <cylinder length="1" radius="0.1"/>
      </geometry>
    </collision>
    <inertial>
      <mass value="0.1"/>
      <inertia ixx="0.03" ixy="0.0" ixz="0.0" iyy="0.03" iyz="0.0" izz="0.03"/>
    </inertial>
    <!--        <gazebo>-->
    <!--            <minDepth>-->
    <!--        </gazebo>-->
  </link>
  <joint name="upper_arm_lower_arm" type="revolute">
    <origin rpy="0 0 0" xyz="1.0 0.0 0.0"/>
    <parent link="upper_arm"/>
    <child link="lower_arm"/>
    <limit effort="100" lower="-3.142" upper="3.142" velocity="100"/>
    <axis xyz="0 0 1"/>
    <gazebo>
      <dynamics damping="0.01"/>
      <dynamics friction="0.01"/>
    </gazebo>
    <!--        ??not sure if this is necessary, should be specified in a gazebo file??-->
    <safety_controller k_position="100.0" k_velocity="40.0" soft_lower_limit="-3.142" soft_upper_limit="3.142"/>
  </joint>
  <link name="gripper_arm">
    <visual>
      <origin rpy="0 1.57079632679 0" xyz="0.1 0 0"/>
      <geometry>
        <cylinder length="0.2" radius="0.05"/>
      </geometry>
      <material name="arm_yellow_mat">
        <color rgba="1 1 0 1.0"/>
      </material>
    </visual>
    <collision>
      <origin rpy="0 1.57079632679 0" xyz="0.1 0 0"/>
      <geometry>
        <cylinder length="0.2" radius="0.05"/>
      </geometry>
    </collision>
    <inertial>
      <mass value="0.1"/>
      <inertia ixx="0.03" ixy="0.0" ixz="0.0" iyy="0.03" iyz="0.0" izz="0.03"/>
    </inertial>
    <!--        <gazebo>-->
    <!--            <minDepth>-->
    <!--        </gazebo>-->
  </link>
  <joint name="lower_arm_gripper_arm" type="revolute">
    <origin rpy="0 0 0" xyz="1.0 0.0 0.0"/>
    <parent link="lower_arm"/>
    <child link="gripper_arm"/>
    <limit effort="100" lower="-3.142" upper="3.142" velocity="100"/>
    <axis xyz="0 0 1"/>
    <gazebo>
      <dynamics damping="0.01"/>
      <dynamics friction="0.01"/>
    </gazebo>
    <!--        ??not sure if this is necessary, should be specified in a gazebo file??-->
    <safety_controller k_position="100.0" k_velocity="40.0" soft_lower_limit="-3.142" soft_upper_limit="3.142"/>
  </joint>
  <link name="end_effector">
    <visual>
      <origin rpy="0 1.57079632679 0" xyz="0.0 0 0"/>
      <geometry>
        <cylinder length="0.01" radius="0.01"/>
      </geometry>
      <material name="arm_yellow_mat">
        <color rgba="1 1 0 1.0"/>
      </material>
    </visual>
    <collision>
      <origin rpy="0 1.57079632679 0" xyz="0.0 0 0"/>
      <geometry>
        <cylinder length="0.01" radius="0.01"/>
      </geometry>
    </collision>
    <inertial>
      <mass value="0.1"/>
      <inertia ixx="0.03" ixy="0.0" ixz="0.0" iyy="0.03" iyz="0.0" izz="0.03"/>
    </inertial>
    <!--        <gazebo>-->
    <!--            <minDepth>-->
    <!--        </gazebo>-->
  </link>
  <joint name="gripper_arm_end_effector" type="fixed">
    <origin rpy="0 0 0" xyz="0.105 0.0 0.0"/>
    <parent link="gripper_arm"/>
    <child link="end_effector"/>
  </joint>
</robot>

