<?xml version="1.0" encoding="utf-8"?>
<!-- =================================================================================== -->
<!-- |    This document was autogenerated by xacro from src/nav_libraries/nuturtle_description/urdf/diff_drive.urdf.xacro | -->
<!-- |    EDITING THIS FILE BY HAND IS NOT RECOMMENDED                                 | -->
<!-- =================================================================================== -->
<robot name="diff_drive">
  <!--    link-->
  <link name="base_link">
    <visual>
      <origin rpy="0 0 0" xyz="0 0 0"/>
      <geometry>
        <box size="0.00001 0.00001 0.00001"/>
      </geometry>
    </visual>
    <inertial>
      <mass value="0.0000001"/>
      <inertia ixx="0.00000001" ixy="0.0" ixz="0.0" iyy="0.0000001" iyz="0.0" izz="0.00000001"/>
    </inertial>
  </link>
  <joint name="base_link_chassis" type="fixed">
    <origin rpy="0.0 0.0 0.0" xyz="0 0  0.013"/>
    <parent link="base_link"/>
    <child link="chassis"/>
  </joint>
  <link name="chassis">
    <visual>
      <origin rpy="0 0 0" xyz="-0.036 0 0.07"/>
      <geometry>
        <box size="0.138 0.142 0.14"/>
      </geometry>
      <material name="arm_pink_mat">
        <color rgba="1.0 0.42 0.72 1.0"/>
      </material>
    </visual>
    <collision>
      <origin rpy="0 0 0" xyz="-0.036 0 0.07"/>
      <geometry>
        <box size="0.138 0.142 0.14"/>
      </geometry>
    </collision>
    <inertial>
      <mass value="1.0"/>
      <inertia ixx="0.00331366666667" ixy="0.0" ixz="0.0" iyy="0.00322033333333" iyz="0.0" izz="0.019604"/>
    </inertial>
  </link>
  <joint name="left_wheel_axle" type="continuous">
    <origin rpy="0 0 0" xyz="0.0 0.08 0.02"/>
    <parent link="chassis"/>
    <child link="left_wheel"/>
    <limit effort="100" velocity="100"/>
    <axis xyz="0 1 0"/>
  </joint>
  <link name="left_wheel">
    <collision>
      <origin rpy="1.57079632679 0 0" xyz="0 0 0"/>
      <geometry>
        <cylinder length="0.018" radius="0.033"/>
      </geometry>
    </collision>
    <visual>
      <origin rpy="1.57079632679 0 0" xyz="0 0 0"/>
      <geometry>
        <cylinder length="0.018" radius="0.033"/>
      </geometry>
      <material name="arm_grey_mat">
        <color rgba="0.75 0.75 0.75 1.0"/>
      </material>
    </visual>
    <inertial>
      <mass value="0.03"/>
      <inertia ixx="8.9775e-06" ixy="0.0" ixz="0.0" iyy="8.9775e-06" iyz="0.0" izz="4.86e-06"/>
    </inertial>
  </link>
  <joint name="right_wheel_axle" type="continuous">
    <origin rpy="0.0 0.0 0.0" xyz="0.0 -0.08 0.02"/>
    <parent link="chassis"/>
    <child link="right_wheel"/>
    <limit effort="100" velocity="100"/>
    <axis xyz="0 1 0"/>
  </joint>
  <link name="right_wheel">
    <collision>
      <origin rpy="1.57079632679 0 0" xyz="0 0 0"/>
      <geometry>
        <cylinder length="0.018" radius="0.033"/>
      </geometry>
    </collision>
    <visual>
      <origin rpy="1.57079632679 0 0" xyz="0 0 0"/>
      <geometry>
        <cylinder length="0.018" radius="0.033"/>
      </geometry>
      <material name="arm_grey_mat">
        <color rgba="0.75 0.75 0.75 1.0"/>
      </material>
    </visual>
    <inertial>
      <mass value="0.03"/>
      <inertia ixx="8.9775e-06" ixy="0.0" ixz="0.0" iyy="8.9775e-06" iyz="0.0" izz="4.86e-06"/>
    </inertial>
  </link>
  <joint name="base_link_ball_caster" type="fixed">
    <origin rpy="0.0 0.0 0.0" xyz="-0.0885 0.0 -0.0065"/>
    <parent link="chassis"/>
    <child link="ball_caster"/>
  </joint>
  <link name="ball_caster">
    <visual>
      <origin rpy="0 0 0" xyz="0 0 0"/>
      <geometry>
        <sphere radius="0.0065"/>
      </geometry>
      <material name="arm_pink_mat">
        <color rgba="1.0 0.42 0.72 1.0"/>
      </material>
    </visual>
    <collision>
      <origin rpy="0 0 0" xyz="0 0 0"/>
      <geometry>
        <sphere radius="0.0065"/>
      </geometry>
    </collision>
    <inertial>
      <mass value="0.03"/>
      <inertia ixx="0.00331366666667" ixy="0.0" ixz="0.0" iyy="0.00322033333333" iyz="0.0" izz="0.019604"/>
    </inertial>
  </link>
  <joint name="chassis_base_scan" type="fixed">
    <origin rpy="0.0 0.0 0.0" xyz="0.0 0.0 0.17"/>
    <parent link="chassis"/>
    <child link="base_scan"/>
  </joint>
  <link name="base_scan">
    <collision>
      <origin rpy="0 0 0" xyz="0 0 -0.02"/>
      <geometry>
        <cylinder length="0.02" radius="0.02"/>
      </geometry>
    </collision>
    <visual>
      <origin rpy="0 0 0" xyz="0 0 -0.02"/>
      <geometry>
        <cylinder length="0.02" radius="0.02"/>
      </geometry>
      <material name="arm_yellow_mat">
        <color rgba="1 1 0 1.0"/>
      </material>
    </visual>
    <inertial>
      <mass value="0.0000001"/>
      <inertia ixx="0.00000001" ixy="0.0" ixz="0.0" iyy="0.0000001" iyz="0.0" izz="0.00000001"/>
    </inertial>
  </link>
</robot>

